2025-03-19 10:41:09.091 WARNING (MainThread) [homeassistant.bootstrap] Setup timed out for stage 1 waiting on {<Task pending name='Task-875' coro=<Store._async_callback_delayed_write() running at /home/vscode/.local/lib/python3.12/site-packages/homeassistant/helpers/storage.py:510> wait_for=<Future pending cb=[_chain_future.<locals>._call_check_cancel() at /usr/local/lib/python3.12/asyncio/futures.py:389, <1 more>, Task.task_wakeup()]> cb=[set.remove()]>} - moving forward
2025-03-19 10:41:09.127 WARNING (MainThread) [homeassistant.bootstrap] Waiting on integrations to complete setup: {('system_health', None): 967.14272734}
2025-03-19 10:41:14.602 ERROR (MainThread) [homeassistant.config_entries] Error occurred loading flow for integration google_translate: No module named 'mutagen'
2025-03-19 10:41:14.602 ERROR (MainThread) [aiohttp.server] Error handling request
Traceback (most recent call last):
  File "/home/vscode/.local/lib/python3.12/site-packages/homeassistant/config_entries.py", line 2587, in _load_integration
    await integration.async_get_platform("config_flow")
  File "/home/vscode/.local/lib/python3.12/site-packages/homeassistant/loader.py", line 1070, in async_get_platform
    platforms = await self.async_get_platforms((platform_name,))
                ^^^^^^^^^^^^^^^^^^^^^^^^^^^^^^^^^^^^^^^^^^^^^^^^
  File "/home/vscode/.local/lib/python3.12/site-packages/homeassistant/loader.py", line 1145, in async_get_platforms
    import_future.result()
  File "/home/vscode/.local/lib/python3.12/site-packages/homeassistant/loader.py", line 1133, in async_get_platforms
    platforms.update(self._load_platforms(platform_names))
                     ^^^^^^^^^^^^^^^^^^^^^^^^^^^^^^^^^^^^
  File "/home/vscode/.local/lib/python3.12/site-packages/homeassistant/loader.py", line 1060, in _load_platforms
    platform_name: self._load_platform(platform_name)
                   ^^^^^^^^^^^^^^^^^^^^^^^^^^^^^^^^^^
  File "/home/vscode/.local/lib/python3.12/site-packages/homeassistant/loader.py", line 1232, in _load_platform
    cache[full_name] = self._import_platform(platform_name)
                       ^^^^^^^^^^^^^^^^^^^^^^^^^^^^^^^^^^^^
  File "/home/vscode/.local/lib/python3.12/site-packages/homeassistant/loader.py", line 1264, in _import_platform
    return importlib.import_module(f"{self.pkg_path}.{platform_name}")
           ^^^^^^^^^^^^^^^^^^^^^^^^^^^^^^^^^^^^^^^^^^^^^^^^^^^^^^^^^^^
  File "/usr/local/lib/python3.12/importlib/__init__.py", line 90, in import_module
    return _bootstrap._gcd_import(name[level:], package, level)
           ^^^^^^^^^^^^^^^^^^^^^^^^^^^^^^^^^^^^^^^^^^^^^^^^^^^^
  File "<frozen importlib._bootstrap>", line 1387, in _gcd_import
  File "<frozen importlib._bootstrap>", line 1360, in _find_and_load
  File "<frozen importlib._bootstrap>", line 1331, in _find_and_load_unlocked
  File "<frozen importlib._bootstrap>", line 935, in _load_unlocked
  File "<frozen importlib._bootstrap_external>", line 999, in exec_module
  File "<frozen importlib._bootstrap>", line 488, in _call_with_frames_removed
  File "/home/vscode/.local/lib/python3.12/site-packages/homeassistant/components/google_translate/config_flow.py", line 9, in <module>
    from homeassistant.components.tts import CONF_LANG
  File "/home/vscode/.local/lib/python3.12/site-packages/homeassistant/components/tts/__init__.py", line 22, in <module>
    import mutagen
ModuleNotFoundError: No module named 'mutagen'

The above exception was the direct cause of the following exception:

Traceback (most recent call last):
  File "/home/vscode/.local/lib/python3.12/site-packages/aiohttp/web_protocol.py", line 452, in _handle_request
    resp = await request_handler(request)
           ^^^^^^^^^^^^^^^^^^^^^^^^^^^^^^
  File "/home/vscode/.local/lib/python3.12/site-packages/aiohttp/web_app.py", line 543, in _handle
    resp = await handler(request)
           ^^^^^^^^^^^^^^^^^^^^^^
  File "/home/vscode/.local/lib/python3.12/site-packages/aiohttp/web_middlewares.py", line 114, in impl
    return await handler(request)
           ^^^^^^^^^^^^^^^^^^^^^^
  File "/home/vscode/.local/lib/python3.12/site-packages/homeassistant/components/http/security_filter.py", line 92, in security_filter_middleware
    return await handler(request)
           ^^^^^^^^^^^^^^^^^^^^^^
  File "/home/vscode/.local/lib/python3.12/site-packages/homeassistant/components/http/forwarded.py", line 83, in forwarded_middleware
    return await handler(request)
           ^^^^^^^^^^^^^^^^^^^^^^
  File "/home/vscode/.local/lib/python3.12/site-packages/homeassistant/components/http/request_context.py", line 26, in request_context_middleware
    return await handler(request)
           ^^^^^^^^^^^^^^^^^^^^^^
  File "/home/vscode/.local/lib/python3.12/site-packages/homeassistant/components/http/ban.py", line 88, in ban_middleware
    return await handler(request)
           ^^^^^^^^^^^^^^^^^^^^^^
  File "/home/vscode/.local/lib/python3.12/site-packages/homeassistant/components/http/auth.py", line 236, in auth_middleware
    return await handler(request)
           ^^^^^^^^^^^^^^^^^^^^^^
  File "/home/vscode/.local/lib/python3.12/site-packages/homeassistant/components/http/headers.py", line 32, in headers_middleware
    response = await handler(request)
               ^^^^^^^^^^^^^^^^^^^^^^
  File "/home/vscode/.local/lib/python3.12/site-packages/homeassistant/helpers/http.py", line 73, in handle
    result = await handler(request, **request.match_info)
             ^^^^^^^^^^^^^^^^^^^^^^^^^^^^^^^^^^^^^^^^^^^^
  File "/home/vscode/.local/lib/python3.12/site-packages/homeassistant/components/onboarding/views.py", line 240, in post
    await asyncio.gather(*(create_eager_task(coro) for coro in coros))
  File "/home/vscode/.local/lib/python3.12/site-packages/homeassistant/config_entries.py", line 1155, in async_init
    flow, result = await self._async_init(flow_id, handler, context, data)
                   ^^^^^^^^^^^^^^^^^^^^^^^^^^^^^^^^^^^^^^^^^^^^^^^^^^^^^^^
  File "/home/vscode/.local/lib/python3.12/site-packages/homeassistant/config_entries.py", line 1175, in _async_init
    flow = await self.async_create_flow(handler, context=context, data=data)
           ^^^^^^^^^^^^^^^^^^^^^^^^^^^^^^^^^^^^^^^^^^^^^^^^^^^^^^^^^^^^^^^^^
  File "/home/vscode/.local/lib/python3.12/site-packages/homeassistant/config_entries.py", line 1312, in async_create_flow
    handler = await _async_get_flow_handler(
              ^^^^^^^^^^^^^^^^^^^^^^^^^^^^^^
  File "/home/vscode/.local/lib/python3.12/site-packages/homeassistant/config_entries.py", line 2608, in _async_get_flow_handler
    await _load_integration(hass, domain, hass_config)
  File "/home/vscode/.local/lib/python3.12/site-packages/homeassistant/config_entries.py", line 2594, in _load_integration
    raise data_entry_flow.UnknownHandler from err
homeassistant.data_entry_flow.UnknownHandler
2025-03-19 10:41:15.847 ERROR (MainThread) [haffmpeg.core] FFmpeg fails [Errno 2] No such file or directory: 'ffmpeg'
Traceback (most recent call last):
  File "/home/vscode/.local/lib/python3.12/site-packages/haffmpeg/core.py", line 130, in open
    self._proc = await asyncio.create_subprocess_exec(
                 ^^^^^^^^^^^^^^^^^^^^^^^^^^^^^^^^^^^^^
  File "/usr/local/lib/python3.12/asyncio/subprocess.py", line 224, in create_subprocess_exec
    transport, protocol = await loop.subprocess_exec(
                          ^^^^^^^^^^^^^^^^^^^^^^^^^^^
  File "/usr/local/lib/python3.12/asyncio/base_events.py", line 1756, in subprocess_exec
    transport = await self._make_subprocess_transport(
                ^^^^^^^^^^^^^^^^^^^^^^^^^^^^^^^^^^^^^^
  File "/usr/local/lib/python3.12/asyncio/unix_events.py", line 211, in _make_subprocess_transport
    transp = _UnixSubprocessTransport(self, protocol, args, shell,
             ^^^^^^^^^^^^^^^^^^^^^^^^^^^^^^^^^^^^^^^^^^^^^^^^^^^^^
  File "/usr/local/lib/python3.12/asyncio/base_subprocess.py", line 36, in __init__
    self._start(args=args, shell=shell, stdin=stdin, stdout=stdout,
  File "/usr/local/lib/python3.12/asyncio/unix_events.py", line 820, in _start
    self._proc = subprocess.Popen(
                 ^^^^^^^^^^^^^^^^^
  File "/usr/local/lib/python3.12/subprocess.py", line 1028, in __init__
    self._execute_child(args, executable, preexec_fn, close_fds,
  File "/usr/local/lib/python3.12/subprocess.py", line 1963, in _execute_child
    raise child_exception_type(errno_num, err_msg, err_filename)
FileNotFoundError: [Errno 2] No such file or directory: 'ffmpeg'
2025-03-19 10:41:15.850 WARNING (MainThread) [haffmpeg.tools] Error starting FFmpeg.
